{
 "cells": [
  {
   "cell_type": "code",
   "execution_count": 16,
   "id": "c68f928e",
   "metadata": {},
   "outputs": [
    {
     "name": "stdout",
     "output_type": "stream",
     "text": [
      "ERROR! Session/line number was not unique in database. History logging moved to new session 652\n"
     ]
    }
   ],
   "source": [
    "import numpy as np\n",
    "import tensorflow as tf\n",
    "from tensorflow import keras\n",
    "\n",
    "import tensorflow_datasets as tf_data\n",
    "import matplotlib.pyplot as plt\n"
   ]
  },
  {
   "cell_type": "code",
   "execution_count": 17,
   "id": "28ee3676",
   "metadata": {},
   "outputs": [],
   "source": [
    "# Preprocess the MNIST images :"
   ]
  },
  {
   "cell_type": "code",
   "execution_count": 24,
   "id": "6d894501",
   "metadata": {},
   "outputs": [
    {
     "name": "stdout",
     "output_type": "stream",
     "text": [
      "ERROR! Session/line number was not unique in database. History logging moved to new session 655\n"
     ]
    }
   ],
   "source": [
    "def map_image(images,label): \n",
    "    # Normalize the image pixels and flatten the image \n",
    "    image = tf.cast(images,dtype=tf.float32)\n",
    "    image = image/255.0\n",
    "    image = np.reshape(image,shape=(28*28*1,))\n",
    "    label = np.reshape(image,shape=(28*28*1,))\n",
    "    \n",
    "    return image, label\n",
    "\n",
    "\n",
    "\n",
    "\n"
   ]
  },
  {
   "cell_type": "code",
   "execution_count": 25,
   "id": "35a05aba",
   "metadata": {},
   "outputs": [],
   "source": [
    "# Split the training the Testing set :"
   ]
  },
  {
   "cell_type": "code",
   "execution_count": 26,
   "id": "5eb3aad2",
   "metadata": {},
   "outputs": [],
   "source": [
    "BATCH_SIZE = 128\n",
    "BUFFER_SIZE = 1024"
   ]
  },
  {
   "cell_type": "code",
   "execution_count": null,
   "id": "83ce6062",
   "metadata": {},
   "outputs": [
    {
     "name": "stderr",
     "output_type": "stream",
     "text": [
      "WARNING:absl:Warning: Setting shuffle_files=True because split=TRAIN and shuffle_files=None. This behavior will be deprecated on 2019-08-06, at which point shuffle_files=False will be the default for all splits.\n"
     ]
    },
    {
     "name": "stdout",
     "output_type": "stream",
     "text": [
      "WARNING:tensorflow:AutoGraph could not transform <bound method TopLevelFeature.decode_example of FeaturesDict({\n",
      "    'image': Image(shape=(28, 28, 1), dtype=tf.uint8),\n",
      "    'label': ClassLabel(shape=(), dtype=tf.int64, num_classes=10),\n",
      "})> and will run it as-is.\n",
      "Please report this to the TensorFlow team. When filing the bug, set the verbosity to 10 (on Linux, `export AUTOGRAPH_VERBOSITY=10`) and attach the full output.\n",
      "Cause: No module named 'tensorflow_core.estimator'\n"
     ]
    },
    {
     "name": "stderr",
     "output_type": "stream",
     "text": [
      "WARNING:tensorflow:AutoGraph could not transform <bound method TopLevelFeature.decode_example of FeaturesDict({\n",
      "    'image': Image(shape=(28, 28, 1), dtype=tf.uint8),\n",
      "    'label': ClassLabel(shape=(), dtype=tf.int64, num_classes=10),\n",
      "})> and will run it as-is.\n",
      "Please report this to the TensorFlow team. When filing the bug, set the verbosity to 10 (on Linux, `export AUTOGRAPH_VERBOSITY=10`) and attach the full output.\n",
      "Cause: No module named 'tensorflow_core.estimator'\n"
     ]
    },
    {
     "name": "stdout",
     "output_type": "stream",
     "text": [
      "WARNING: AutoGraph could not transform <bound method TopLevelFeature.decode_example of FeaturesDict({\n",
      "    'image': Image(shape=(28, 28, 1), dtype=tf.uint8),\n",
      "    'label': ClassLabel(shape=(), dtype=tf.int64, num_classes=10),\n",
      "})> and will run it as-is.\n",
      "Please report this to the TensorFlow team. When filing the bug, set the verbosity to 10 (on Linux, `export AUTOGRAPH_VERBOSITY=10`) and attach the full output.\n",
      "Cause: No module named 'tensorflow_core.estimator'\n",
      "WARNING:tensorflow:AutoGraph could not transform <function map_image at 0x0000027EA9CF7F28> and will run it as-is.\n",
      "Please report this to the TensorFlow team. When filing the bug, set the verbosity to 10 (on Linux, `export AUTOGRAPH_VERBOSITY=10`) and attach the full output.\n",
      "Cause: No module named 'tensorflow_core.estimator'\n"
     ]
    },
    {
     "name": "stderr",
     "output_type": "stream",
     "text": [
      "WARNING:tensorflow:AutoGraph could not transform <function map_image at 0x0000027EA9CF7F28> and will run it as-is.\n",
      "Please report this to the TensorFlow team. When filing the bug, set the verbosity to 10 (on Linux, `export AUTOGRAPH_VERBOSITY=10`) and attach the full output.\n",
      "Cause: No module named 'tensorflow_core.estimator'\n",
      "ERROR:root:Internal Python error in the inspect module.\n",
      "Below is the traceback from this internal error.\n",
      "\n",
      "ERROR:root:Internal Python error in the inspect module.\n",
      "Below is the traceback from this internal error.\n",
      "\n",
      "ERROR:root:Internal Python error in the inspect module.\n",
      "Below is the traceback from this internal error.\n",
      "\n"
     ]
    },
    {
     "name": "stdout",
     "output_type": "stream",
     "text": [
      "WARNING: AutoGraph could not transform <function map_image at 0x0000027EA9CF7F28> and will run it as-is.\n",
      "Please report this to the TensorFlow team. When filing the bug, set the verbosity to 10 (on Linux, `export AUTOGRAPH_VERBOSITY=10`) and attach the full output.\n",
      "Cause: No module named 'tensorflow_core.estimator'\n",
      "Traceback (most recent call last):\n",
      "  File \"D:\\SOFTWARE\\Anaconda\\envs\\gpu_tf\\lib\\site-packages\\IPython\\core\\interactiveshell.py\", line 3343, in run_code\n",
      "    exec(code_obj, self.user_global_ns, self.user_ns)\n",
      "  File \"<ipython-input-27-da4c12182283>\", line 2, in <module>\n",
      "    train_dataset = train_dataset.map(map_image)\n",
      "  File \"D:\\SOFTWARE\\Anaconda\\envs\\gpu_tf\\lib\\site-packages\\tensorflow_core\\python\\data\\ops\\dataset_ops.py\", line 1588, in map\n",
      "    return MapDataset(self, map_func, preserve_cardinality=True)\n",
      "  File \"D:\\SOFTWARE\\Anaconda\\envs\\gpu_tf\\lib\\site-packages\\tensorflow_core\\python\\data\\ops\\dataset_ops.py\", line 3888, in __init__\n",
      "    use_legacy_function=use_legacy_function)\n",
      "  File \"D:\\SOFTWARE\\Anaconda\\envs\\gpu_tf\\lib\\site-packages\\tensorflow_core\\python\\data\\ops\\dataset_ops.py\", line 3147, in __init__\n",
      "    self._function = wrapper_fn._get_concrete_function_internal()\n",
      "  File \"D:\\SOFTWARE\\Anaconda\\envs\\gpu_tf\\lib\\site-packages\\tensorflow_core\\python\\eager\\function.py\", line 2395, in _get_concrete_function_internal\n",
      "    *args, **kwargs)\n",
      "  File \"D:\\SOFTWARE\\Anaconda\\envs\\gpu_tf\\lib\\site-packages\\tensorflow_core\\python\\eager\\function.py\", line 2389, in _get_concrete_function_internal_garbage_collected\n",
      "    graph_function, _, _ = self._maybe_define_function(args, kwargs)\n",
      "  File \"D:\\SOFTWARE\\Anaconda\\envs\\gpu_tf\\lib\\site-packages\\tensorflow_core\\python\\eager\\function.py\", line 2703, in _maybe_define_function\n",
      "    graph_function = self._create_graph_function(args, kwargs)\n",
      "  File \"D:\\SOFTWARE\\Anaconda\\envs\\gpu_tf\\lib\\site-packages\\tensorflow_core\\python\\eager\\function.py\", line 2593, in _create_graph_function\n",
      "    capture_by_value=self._capture_by_value),\n",
      "  File \"D:\\SOFTWARE\\Anaconda\\envs\\gpu_tf\\lib\\site-packages\\tensorflow_core\\python\\framework\\func_graph.py\", line 978, in func_graph_from_py_func\n",
      "    func_outputs = python_func(*func_args, **func_kwargs)\n",
      "  File \"D:\\SOFTWARE\\Anaconda\\envs\\gpu_tf\\lib\\site-packages\\tensorflow_core\\python\\data\\ops\\dataset_ops.py\", line 3140, in wrapper_fn\n",
      "    ret = _wrapper_helper(*args)\n",
      "  File \"D:\\SOFTWARE\\Anaconda\\envs\\gpu_tf\\lib\\site-packages\\tensorflow_core\\python\\data\\ops\\dataset_ops.py\", line 3082, in _wrapper_helper\n",
      "    ret = autograph.tf_convert(func, ag_ctx)(*nested_args)\n",
      "  File \"D:\\SOFTWARE\\Anaconda\\envs\\gpu_tf\\lib\\site-packages\\tensorflow_core\\python\\autograph\\impl\\api.py\", line 237, in wrapper\n",
      "    raise e.ag_error_metadata.to_exception(e)\n",
      "TypeError: in converted code:\n",
      "\n",
      "    <ipython-input-24-f1f025c6da44>:5 map_image\n",
      "        image = np.reshape(image,shape=(28*28*1,))\n",
      "    <__array_function__ internals>:4 reshape\n",
      "        \n",
      "\n",
      "    TypeError: _reshape_dispatcher() got an unexpected keyword argument 'shape'\n",
      "\n",
      "\n",
      "During handling of the above exception, another exception occurred:\n",
      "\n",
      "Traceback (most recent call last):\n",
      "  File \"D:\\SOFTWARE\\Anaconda\\envs\\gpu_tf\\lib\\site-packages\\IPython\\core\\interactiveshell.py\", line 2044, in showtraceback\n",
      "    stb = value._render_traceback_()\n",
      "AttributeError: 'TypeError' object has no attribute '_render_traceback_'\n",
      "\n",
      "During handling of the above exception, another exception occurred:\n",
      "\n",
      "Traceback (most recent call last):\n",
      "  File \"D:\\SOFTWARE\\Anaconda\\envs\\gpu_tf\\lib\\site-packages\\IPython\\core\\ultratb.py\", line 1169, in get_records\n",
      "    return _fixed_getinnerframes(etb, number_of_lines_of_context, tb_offset)\n",
      "  File \"D:\\SOFTWARE\\Anaconda\\envs\\gpu_tf\\lib\\site-packages\\IPython\\core\\ultratb.py\", line 316, in wrapped\n",
      "    return f(*args, **kwargs)\n",
      "  File \"D:\\SOFTWARE\\Anaconda\\envs\\gpu_tf\\lib\\site-packages\\IPython\\core\\ultratb.py\", line 350, in _fixed_getinnerframes\n",
      "    records = fix_frame_records_filenames(inspect.getinnerframes(etb, context))\n",
      "  File \"D:\\SOFTWARE\\Anaconda\\envs\\gpu_tf\\lib\\inspect.py\", line 1490, in getinnerframes\n",
      "    frameinfo = (tb.tb_frame,) + getframeinfo(tb, context)\n",
      "  File \"D:\\SOFTWARE\\Anaconda\\envs\\gpu_tf\\lib\\inspect.py\", line 1448, in getframeinfo\n",
      "    filename = getsourcefile(frame) or getfile(frame)\n",
      "  File \"D:\\SOFTWARE\\Anaconda\\envs\\gpu_tf\\lib\\inspect.py\", line 696, in getsourcefile\n",
      "    if getattr(getmodule(object, filename), '__loader__', None) is not None:\n",
      "  File \"D:\\SOFTWARE\\Anaconda\\envs\\gpu_tf\\lib\\inspect.py\", line 733, in getmodule\n",
      "    if ismodule(module) and hasattr(module, '__file__'):\n",
      "  File \"D:\\SOFTWARE\\Anaconda\\envs\\gpu_tf\\lib\\site-packages\\tensorflow\\__init__.py\", line 50, in __getattr__\n",
      "    module = self._load()\n",
      "  File \"D:\\SOFTWARE\\Anaconda\\envs\\gpu_tf\\lib\\site-packages\\tensorflow\\__init__.py\", line 44, in _load\n",
      "    module = _importlib.import_module(self.__name__)\n",
      "  File \"D:\\SOFTWARE\\Anaconda\\envs\\gpu_tf\\lib\\importlib\\__init__.py\", line 126, in import_module\n",
      "    return _bootstrap._gcd_import(name[level:], package, level)\n",
      "  File \"<frozen importlib._bootstrap>\", line 994, in _gcd_import\n",
      "  File \"<frozen importlib._bootstrap>\", line 971, in _find_and_load\n",
      "  File \"<frozen importlib._bootstrap>\", line 953, in _find_and_load_unlocked\n",
      "ModuleNotFoundError: No module named 'tensorflow_core.estimator'\n",
      "Traceback (most recent call last):\n",
      "  File \"D:\\SOFTWARE\\Anaconda\\envs\\gpu_tf\\lib\\site-packages\\IPython\\core\\interactiveshell.py\", line 3343, in run_code\n",
      "    exec(code_obj, self.user_global_ns, self.user_ns)\n",
      "  File \"<ipython-input-27-da4c12182283>\", line 2, in <module>\n",
      "    train_dataset = train_dataset.map(map_image)\n",
      "  File \"D:\\SOFTWARE\\Anaconda\\envs\\gpu_tf\\lib\\site-packages\\tensorflow_core\\python\\data\\ops\\dataset_ops.py\", line 1588, in map\n",
      "    return MapDataset(self, map_func, preserve_cardinality=True)\n",
      "  File \"D:\\SOFTWARE\\Anaconda\\envs\\gpu_tf\\lib\\site-packages\\tensorflow_core\\python\\data\\ops\\dataset_ops.py\", line 3888, in __init__\n",
      "    use_legacy_function=use_legacy_function)\n",
      "  File \"D:\\SOFTWARE\\Anaconda\\envs\\gpu_tf\\lib\\site-packages\\tensorflow_core\\python\\data\\ops\\dataset_ops.py\", line 3147, in __init__\n",
      "    self._function = wrapper_fn._get_concrete_function_internal()\n",
      "  File \"D:\\SOFTWARE\\Anaconda\\envs\\gpu_tf\\lib\\site-packages\\tensorflow_core\\python\\eager\\function.py\", line 2395, in _get_concrete_function_internal\n",
      "    *args, **kwargs)\n",
      "  File \"D:\\SOFTWARE\\Anaconda\\envs\\gpu_tf\\lib\\site-packages\\tensorflow_core\\python\\eager\\function.py\", line 2389, in _get_concrete_function_internal_garbage_collected\n",
      "    graph_function, _, _ = self._maybe_define_function(args, kwargs)\n",
      "  File \"D:\\SOFTWARE\\Anaconda\\envs\\gpu_tf\\lib\\site-packages\\tensorflow_core\\python\\eager\\function.py\", line 2703, in _maybe_define_function\n",
      "    graph_function = self._create_graph_function(args, kwargs)\n",
      "  File \"D:\\SOFTWARE\\Anaconda\\envs\\gpu_tf\\lib\\site-packages\\tensorflow_core\\python\\eager\\function.py\", line 2593, in _create_graph_function\n",
      "    capture_by_value=self._capture_by_value),\n",
      "  File \"D:\\SOFTWARE\\Anaconda\\envs\\gpu_tf\\lib\\site-packages\\tensorflow_core\\python\\framework\\func_graph.py\", line 978, in func_graph_from_py_func\n",
      "    func_outputs = python_func(*func_args, **func_kwargs)\n",
      "  File \"D:\\SOFTWARE\\Anaconda\\envs\\gpu_tf\\lib\\site-packages\\tensorflow_core\\python\\data\\ops\\dataset_ops.py\", line 3140, in wrapper_fn\n",
      "    ret = _wrapper_helper(*args)\n",
      "  File \"D:\\SOFTWARE\\Anaconda\\envs\\gpu_tf\\lib\\site-packages\\tensorflow_core\\python\\data\\ops\\dataset_ops.py\", line 3082, in _wrapper_helper\n",
      "    ret = autograph.tf_convert(func, ag_ctx)(*nested_args)\n",
      "  File \"D:\\SOFTWARE\\Anaconda\\envs\\gpu_tf\\lib\\site-packages\\tensorflow_core\\python\\autograph\\impl\\api.py\", line 237, in wrapper\n",
      "    raise e.ag_error_metadata.to_exception(e)\n",
      "TypeError: in converted code:\n",
      "\n",
      "    <ipython-input-24-f1f025c6da44>:5 map_image\n",
      "        image = np.reshape(image,shape=(28*28*1,))\n",
      "    <__array_function__ internals>:4 reshape\n",
      "        \n",
      "\n",
      "    TypeError: _reshape_dispatcher() got an unexpected keyword argument 'shape'\n",
      "\n",
      "\n",
      "During handling of the above exception, another exception occurred:\n",
      "\n",
      "Traceback (most recent call last):\n",
      "  File \"D:\\SOFTWARE\\Anaconda\\envs\\gpu_tf\\lib\\site-packages\\IPython\\core\\interactiveshell.py\", line 2044, in showtraceback\n",
      "    stb = value._render_traceback_()\n",
      "AttributeError: 'TypeError' object has no attribute '_render_traceback_'\n",
      "\n",
      "During handling of the above exception, another exception occurred:\n",
      "\n",
      "Traceback (most recent call last):\n",
      "  File \"D:\\SOFTWARE\\Anaconda\\envs\\gpu_tf\\lib\\site-packages\\IPython\\core\\interactiveshell.py\", line 3263, in run_ast_nodes\n",
      "    if (await self.run_code(code, result,  async_=asy)):\n",
      "  File \"D:\\SOFTWARE\\Anaconda\\envs\\gpu_tf\\lib\\site-packages\\IPython\\core\\interactiveshell.py\", line 3360, in run_code\n",
      "    self.showtraceback(running_compiled_code=True)\n",
      "  File \"D:\\SOFTWARE\\Anaconda\\envs\\gpu_tf\\lib\\site-packages\\IPython\\core\\interactiveshell.py\", line 2047, in showtraceback\n",
      "    value, tb, tb_offset=tb_offset)\n",
      "  File \"D:\\SOFTWARE\\Anaconda\\envs\\gpu_tf\\lib\\site-packages\\IPython\\core\\ultratb.py\", line 1436, in structured_traceback\n",
      "    self, etype, value, tb, tb_offset, number_of_lines_of_context)\n",
      "  File \"D:\\SOFTWARE\\Anaconda\\envs\\gpu_tf\\lib\\site-packages\\IPython\\core\\ultratb.py\", line 1336, in structured_traceback\n",
      "    self, etype, value, tb, tb_offset, number_of_lines_of_context\n",
      "  File \"D:\\SOFTWARE\\Anaconda\\envs\\gpu_tf\\lib\\site-packages\\IPython\\core\\ultratb.py\", line 1193, in structured_traceback\n",
      "    tb_offset)\n",
      "  File \"D:\\SOFTWARE\\Anaconda\\envs\\gpu_tf\\lib\\site-packages\\IPython\\core\\ultratb.py\", line 1150, in format_exception_as_a_whole\n",
      "    last_unique, recursion_repeat = find_recursion(orig_etype, evalue, records)\n",
      "  File \"D:\\SOFTWARE\\Anaconda\\envs\\gpu_tf\\lib\\site-packages\\IPython\\core\\ultratb.py\", line 451, in find_recursion\n",
      "    return len(records), 0\n",
      "TypeError: object of type 'NoneType' has no len()\n",
      "\n",
      "During handling of the above exception, another exception occurred:\n",
      "\n",
      "Traceback (most recent call last):\n",
      "  File \"D:\\SOFTWARE\\Anaconda\\envs\\gpu_tf\\lib\\site-packages\\IPython\\core\\interactiveshell.py\", line 2044, in showtraceback\n",
      "    stb = value._render_traceback_()\n",
      "AttributeError: 'TypeError' object has no attribute '_render_traceback_'\n",
      "\n",
      "During handling of the above exception, another exception occurred:\n",
      "\n",
      "Traceback (most recent call last):\n",
      "  File \"D:\\SOFTWARE\\Anaconda\\envs\\gpu_tf\\lib\\site-packages\\IPython\\core\\ultratb.py\", line 1169, in get_records\n",
      "    return _fixed_getinnerframes(etb, number_of_lines_of_context, tb_offset)\n",
      "  File \"D:\\SOFTWARE\\Anaconda\\envs\\gpu_tf\\lib\\site-packages\\IPython\\core\\ultratb.py\", line 316, in wrapped\n",
      "    return f(*args, **kwargs)\n",
      "  File \"D:\\SOFTWARE\\Anaconda\\envs\\gpu_tf\\lib\\site-packages\\IPython\\core\\ultratb.py\", line 350, in _fixed_getinnerframes\n",
      "    records = fix_frame_records_filenames(inspect.getinnerframes(etb, context))\n",
      "  File \"D:\\SOFTWARE\\Anaconda\\envs\\gpu_tf\\lib\\inspect.py\", line 1490, in getinnerframes\n",
      "    frameinfo = (tb.tb_frame,) + getframeinfo(tb, context)\n",
      "  File \"D:\\SOFTWARE\\Anaconda\\envs\\gpu_tf\\lib\\inspect.py\", line 1448, in getframeinfo\n",
      "    filename = getsourcefile(frame) or getfile(frame)\n",
      "  File \"D:\\SOFTWARE\\Anaconda\\envs\\gpu_tf\\lib\\inspect.py\", line 696, in getsourcefile\n",
      "    if getattr(getmodule(object, filename), '__loader__', None) is not None:\n",
      "  File \"D:\\SOFTWARE\\Anaconda\\envs\\gpu_tf\\lib\\inspect.py\", line 733, in getmodule\n",
      "    if ismodule(module) and hasattr(module, '__file__'):\n",
      "  File \"D:\\SOFTWARE\\Anaconda\\envs\\gpu_tf\\lib\\site-packages\\tensorflow\\__init__.py\", line 50, in __getattr__\n",
      "    module = self._load()\n",
      "  File \"D:\\SOFTWARE\\Anaconda\\envs\\gpu_tf\\lib\\site-packages\\tensorflow\\__init__.py\", line 44, in _load\n",
      "    module = _importlib.import_module(self.__name__)\n",
      "  File \"D:\\SOFTWARE\\Anaconda\\envs\\gpu_tf\\lib\\importlib\\__init__.py\", line 126, in import_module\n",
      "    return _bootstrap._gcd_import(name[level:], package, level)\n",
      "  File \"<frozen importlib._bootstrap>\", line 994, in _gcd_import\n",
      "  File \"<frozen importlib._bootstrap>\", line 971, in _find_and_load\n",
      "  File \"<frozen importlib._bootstrap>\", line 953, in _find_and_load_unlocked\n",
      "ModuleNotFoundError: No module named 'tensorflow_core.estimator'\n",
      "Traceback (most recent call last):\n",
      "  File \"D:\\SOFTWARE\\Anaconda\\envs\\gpu_tf\\lib\\site-packages\\IPython\\core\\interactiveshell.py\", line 3343, in run_code\n",
      "    exec(code_obj, self.user_global_ns, self.user_ns)\n",
      "  File \"<ipython-input-27-da4c12182283>\", line 2, in <module>\n",
      "    train_dataset = train_dataset.map(map_image)\n",
      "  File \"D:\\SOFTWARE\\Anaconda\\envs\\gpu_tf\\lib\\site-packages\\tensorflow_core\\python\\data\\ops\\dataset_ops.py\", line 1588, in map\n",
      "    return MapDataset(self, map_func, preserve_cardinality=True)\n",
      "  File \"D:\\SOFTWARE\\Anaconda\\envs\\gpu_tf\\lib\\site-packages\\tensorflow_core\\python\\data\\ops\\dataset_ops.py\", line 3888, in __init__\n",
      "    use_legacy_function=use_legacy_function)\n",
      "  File \"D:\\SOFTWARE\\Anaconda\\envs\\gpu_tf\\lib\\site-packages\\tensorflow_core\\python\\data\\ops\\dataset_ops.py\", line 3147, in __init__\n",
      "    self._function = wrapper_fn._get_concrete_function_internal()\n",
      "  File \"D:\\SOFTWARE\\Anaconda\\envs\\gpu_tf\\lib\\site-packages\\tensorflow_core\\python\\eager\\function.py\", line 2395, in _get_concrete_function_internal\n",
      "    *args, **kwargs)\n",
      "  File \"D:\\SOFTWARE\\Anaconda\\envs\\gpu_tf\\lib\\site-packages\\tensorflow_core\\python\\eager\\function.py\", line 2389, in _get_concrete_function_internal_garbage_collected\n",
      "    graph_function, _, _ = self._maybe_define_function(args, kwargs)\n",
      "  File \"D:\\SOFTWARE\\Anaconda\\envs\\gpu_tf\\lib\\site-packages\\tensorflow_core\\python\\eager\\function.py\", line 2703, in _maybe_define_function\n",
      "    graph_function = self._create_graph_function(args, kwargs)\n",
      "  File \"D:\\SOFTWARE\\Anaconda\\envs\\gpu_tf\\lib\\site-packages\\tensorflow_core\\python\\eager\\function.py\", line 2593, in _create_graph_function\n",
      "    capture_by_value=self._capture_by_value),\n",
      "  File \"D:\\SOFTWARE\\Anaconda\\envs\\gpu_tf\\lib\\site-packages\\tensorflow_core\\python\\framework\\func_graph.py\", line 978, in func_graph_from_py_func\n",
      "    func_outputs = python_func(*func_args, **func_kwargs)\n",
      "  File \"D:\\SOFTWARE\\Anaconda\\envs\\gpu_tf\\lib\\site-packages\\tensorflow_core\\python\\data\\ops\\dataset_ops.py\", line 3140, in wrapper_fn\n",
      "    ret = _wrapper_helper(*args)\n",
      "  File \"D:\\SOFTWARE\\Anaconda\\envs\\gpu_tf\\lib\\site-packages\\tensorflow_core\\python\\data\\ops\\dataset_ops.py\", line 3082, in _wrapper_helper\n",
      "    ret = autograph.tf_convert(func, ag_ctx)(*nested_args)\n",
      "  File \"D:\\SOFTWARE\\Anaconda\\envs\\gpu_tf\\lib\\site-packages\\tensorflow_core\\python\\autograph\\impl\\api.py\", line 237, in wrapper\n",
      "    raise e.ag_error_metadata.to_exception(e)\n",
      "TypeError: in converted code:\n",
      "\n",
      "    <ipython-input-24-f1f025c6da44>:5 map_image\n",
      "        image = np.reshape(image,shape=(28*28*1,))\n",
      "    <__array_function__ internals>:4 reshape\n",
      "        \n",
      "\n",
      "    TypeError: _reshape_dispatcher() got an unexpected keyword argument 'shape'\n",
      "\n",
      "\n",
      "During handling of the above exception, another exception occurred:\n",
      "\n",
      "Traceback (most recent call last):\n",
      "  File \"D:\\SOFTWARE\\Anaconda\\envs\\gpu_tf\\lib\\site-packages\\IPython\\core\\interactiveshell.py\", line 2044, in showtraceback\n",
      "    stb = value._render_traceback_()\n",
      "AttributeError: 'TypeError' object has no attribute '_render_traceback_'\n",
      "\n",
      "During handling of the above exception, another exception occurred:\n",
      "\n",
      "Traceback (most recent call last):\n",
      "  File \"D:\\SOFTWARE\\Anaconda\\envs\\gpu_tf\\lib\\site-packages\\IPython\\core\\interactiveshell.py\", line 3263, in run_ast_nodes\n",
      "    if (await self.run_code(code, result,  async_=asy)):\n",
      "  File \"D:\\SOFTWARE\\Anaconda\\envs\\gpu_tf\\lib\\site-packages\\IPython\\core\\interactiveshell.py\", line 3360, in run_code\n",
      "    self.showtraceback(running_compiled_code=True)\n",
      "  File \"D:\\SOFTWARE\\Anaconda\\envs\\gpu_tf\\lib\\site-packages\\IPython\\core\\interactiveshell.py\", line 2047, in showtraceback\n",
      "    value, tb, tb_offset=tb_offset)\n",
      "  File \"D:\\SOFTWARE\\Anaconda\\envs\\gpu_tf\\lib\\site-packages\\IPython\\core\\ultratb.py\", line 1436, in structured_traceback\n",
      "    self, etype, value, tb, tb_offset, number_of_lines_of_context)\n",
      "  File \"D:\\SOFTWARE\\Anaconda\\envs\\gpu_tf\\lib\\site-packages\\IPython\\core\\ultratb.py\", line 1336, in structured_traceback\n",
      "    self, etype, value, tb, tb_offset, number_of_lines_of_context\n",
      "  File \"D:\\SOFTWARE\\Anaconda\\envs\\gpu_tf\\lib\\site-packages\\IPython\\core\\ultratb.py\", line 1193, in structured_traceback\n",
      "    tb_offset)\n",
      "  File \"D:\\SOFTWARE\\Anaconda\\envs\\gpu_tf\\lib\\site-packages\\IPython\\core\\ultratb.py\", line 1150, in format_exception_as_a_whole\n",
      "    last_unique, recursion_repeat = find_recursion(orig_etype, evalue, records)\n",
      "  File \"D:\\SOFTWARE\\Anaconda\\envs\\gpu_tf\\lib\\site-packages\\IPython\\core\\ultratb.py\", line 451, in find_recursion\n",
      "    return len(records), 0\n",
      "TypeError: object of type 'NoneType' has no len()\n",
      "\n",
      "During handling of the above exception, another exception occurred:\n",
      "\n",
      "Traceback (most recent call last):\n",
      "  File \"D:\\SOFTWARE\\Anaconda\\envs\\gpu_tf\\lib\\site-packages\\IPython\\core\\interactiveshell.py\", line 2044, in showtraceback\n",
      "    stb = value._render_traceback_()\n",
      "AttributeError: 'TypeError' object has no attribute '_render_traceback_'\n",
      "\n",
      "During handling of the above exception, another exception occurred:\n",
      "\n",
      "Traceback (most recent call last):\n",
      "  File \"D:\\SOFTWARE\\Anaconda\\envs\\gpu_tf\\lib\\site-packages\\IPython\\core\\interactiveshell.py\", line 2895, in _run_cell\n",
      "    return runner(coro)\n",
      "  File \"D:\\SOFTWARE\\Anaconda\\envs\\gpu_tf\\lib\\site-packages\\IPython\\core\\async_helpers.py\", line 68, in _pseudo_sync_runner\n",
      "    coro.send(None)\n",
      "  File \"D:\\SOFTWARE\\Anaconda\\envs\\gpu_tf\\lib\\site-packages\\IPython\\core\\interactiveshell.py\", line 3072, in run_cell_async\n",
      "    interactivity=interactivity, compiler=compiler, result=result)\n",
      "  File \"D:\\SOFTWARE\\Anaconda\\envs\\gpu_tf\\lib\\site-packages\\IPython\\core\\interactiveshell.py\", line 3282, in run_ast_nodes\n",
      "    self.showtraceback()\n",
      "  File \"D:\\SOFTWARE\\Anaconda\\envs\\gpu_tf\\lib\\site-packages\\IPython\\core\\interactiveshell.py\", line 2047, in showtraceback\n",
      "    value, tb, tb_offset=tb_offset)\n",
      "  File \"D:\\SOFTWARE\\Anaconda\\envs\\gpu_tf\\lib\\site-packages\\IPython\\core\\ultratb.py\", line 1436, in structured_traceback\n",
      "    self, etype, value, tb, tb_offset, number_of_lines_of_context)\n",
      "  File \"D:\\SOFTWARE\\Anaconda\\envs\\gpu_tf\\lib\\site-packages\\IPython\\core\\ultratb.py\", line 1336, in structured_traceback\n",
      "    self, etype, value, tb, tb_offset, number_of_lines_of_context\n",
      "  File \"D:\\SOFTWARE\\Anaconda\\envs\\gpu_tf\\lib\\site-packages\\IPython\\core\\ultratb.py\", line 1211, in structured_traceback\n",
      "    chained_exceptions_tb_offset)\n",
      "  File \"D:\\SOFTWARE\\Anaconda\\envs\\gpu_tf\\lib\\site-packages\\IPython\\core\\ultratb.py\", line 1150, in format_exception_as_a_whole\n",
      "    last_unique, recursion_repeat = find_recursion(orig_etype, evalue, records)\n",
      "  File \"D:\\SOFTWARE\\Anaconda\\envs\\gpu_tf\\lib\\site-packages\\IPython\\core\\ultratb.py\", line 451, in find_recursion\n",
      "    return len(records), 0\n",
      "TypeError: object of type 'NoneType' has no len()\n",
      "\n",
      "During handling of the above exception, another exception occurred:\n",
      "\n",
      "Traceback (most recent call last):\n",
      "  File \"D:\\SOFTWARE\\Anaconda\\envs\\gpu_tf\\lib\\site-packages\\IPython\\core\\interactiveshell.py\", line 2044, in showtraceback\n",
      "    stb = value._render_traceback_()\n",
      "AttributeError: 'TypeError' object has no attribute '_render_traceback_'\n",
      "\n",
      "During handling of the above exception, another exception occurred:\n",
      "\n",
      "Traceback (most recent call last):\n",
      "  File \"D:\\SOFTWARE\\Anaconda\\envs\\gpu_tf\\lib\\site-packages\\IPython\\core\\ultratb.py\", line 1169, in get_records\n",
      "    return _fixed_getinnerframes(etb, number_of_lines_of_context, tb_offset)\n",
      "  File \"D:\\SOFTWARE\\Anaconda\\envs\\gpu_tf\\lib\\site-packages\\IPython\\core\\ultratb.py\", line 316, in wrapped\n",
      "    return f(*args, **kwargs)\n",
      "  File \"D:\\SOFTWARE\\Anaconda\\envs\\gpu_tf\\lib\\site-packages\\IPython\\core\\ultratb.py\", line 350, in _fixed_getinnerframes\n",
      "    records = fix_frame_records_filenames(inspect.getinnerframes(etb, context))\n",
      "  File \"D:\\SOFTWARE\\Anaconda\\envs\\gpu_tf\\lib\\inspect.py\", line 1490, in getinnerframes\n",
      "    frameinfo = (tb.tb_frame,) + getframeinfo(tb, context)\n",
      "  File \"D:\\SOFTWARE\\Anaconda\\envs\\gpu_tf\\lib\\inspect.py\", line 1448, in getframeinfo\n",
      "    filename = getsourcefile(frame) or getfile(frame)\n",
      "  File \"D:\\SOFTWARE\\Anaconda\\envs\\gpu_tf\\lib\\inspect.py\", line 696, in getsourcefile\n",
      "    if getattr(getmodule(object, filename), '__loader__', None) is not None:\n",
      "  File \"D:\\SOFTWARE\\Anaconda\\envs\\gpu_tf\\lib\\inspect.py\", line 733, in getmodule\n",
      "    if ismodule(module) and hasattr(module, '__file__'):\n",
      "  File \"D:\\SOFTWARE\\Anaconda\\envs\\gpu_tf\\lib\\site-packages\\tensorflow\\__init__.py\", line 50, in __getattr__\n",
      "    module = self._load()\n",
      "  File \"D:\\SOFTWARE\\Anaconda\\envs\\gpu_tf\\lib\\site-packages\\tensorflow\\__init__.py\", line 44, in _load\n",
      "    module = _importlib.import_module(self.__name__)\n",
      "  File \"D:\\SOFTWARE\\Anaconda\\envs\\gpu_tf\\lib\\importlib\\__init__.py\", line 126, in import_module\n",
      "    return _bootstrap._gcd_import(name[level:], package, level)\n",
      "  File \"<frozen importlib._bootstrap>\", line 994, in _gcd_import\n",
      "  File \"<frozen importlib._bootstrap>\", line 971, in _find_and_load\n",
      "  File \"<frozen importlib._bootstrap>\", line 953, in _find_and_load_unlocked\n",
      "ModuleNotFoundError: No module named 'tensorflow_core.estimator'\n"
     ]
    }
   ],
   "source": [
    "train_dataset = tf_data.load(\"mnist\",as_supervised=True,split='train')\n",
    "train_dataset = train_dataset.map(map_image)\n",
    "train_dataset = train_dataset.shuffle(BATCH_SIZE).batch(BATCH_SIZE).repeat()\n",
    "\n",
    "test_datasets = tf_data.load('mnist',as_supervised=True,split='test')\n",
    "test_datasets = test_datasets.map(map_image)\n",
    "test_datasets = test_datasets.batch(BATCH_SIZE).repeat()\n"
   ]
  },
  {
   "cell_type": "code",
   "execution_count": null,
   "id": "77860ec3",
   "metadata": {},
   "outputs": [],
   "source": []
  },
  {
   "cell_type": "code",
   "execution_count": null,
   "id": "afd4b7b8",
   "metadata": {},
   "outputs": [],
   "source": []
  },
  {
   "cell_type": "code",
   "execution_count": null,
   "id": "9f4a11bc",
   "metadata": {},
   "outputs": [],
   "source": []
  },
  {
   "cell_type": "code",
   "execution_count": null,
   "id": "29a39d27",
   "metadata": {},
   "outputs": [],
   "source": []
  },
  {
   "cell_type": "code",
   "execution_count": null,
   "id": "df07e731",
   "metadata": {},
   "outputs": [],
   "source": []
  }
 ],
 "metadata": {
  "kernelspec": {
   "display_name": "Python 3",
   "language": "python",
   "name": "python3"
  },
  "language_info": {
   "codemirror_mode": {
    "name": "ipython",
    "version": 3
   },
   "file_extension": ".py",
   "mimetype": "text/x-python",
   "name": "python",
   "nbconvert_exporter": "python",
   "pygments_lexer": "ipython3",
   "version": "3.6.13"
  }
 },
 "nbformat": 4,
 "nbformat_minor": 5
}
